Workbook

Sheet Summary
A1: Riverbend Produce Limited
A2: Coolstore 3 — Glycol Chilling Upgrade
A3: Q900142 · Rev A
A5: Built from | B5: specification + preliminary P&ID
A6: Lines | B6: 54
A7: Awaiting supplier / subcontractor price | B7: 13
A8: Engineer to enter | B8: 30
A9: Rules to confirm | B9: 11
A11: Cost | B11: =Costing!I1000
A12: Margin | B12: 0.15
A13: Sell
A15: Exchange rate assumed | B15: NZ$1 = USD $0.58

Sheet Schedule of prices
A1: Ref | B1: Description | C1: Cost | D1: Sell
A2: 7.1 | B2: Compressor pack, including drives
A3: 7.2 | B3: Evaporative condenser
A4: 7.3 | B4: Chiller plate heat exchanger
A5: 7.4 | B5: Glycol circulation — pumps, tanks and controls
A6: 7.5 | B6: Unit coolers
A7: 7.6 | B7: Glycol pipework, valves and insulation
A8: 7.7 | B8: Installation labour, supervision and consumables
A9: 7.8 | B9: Electrical power, control wiring and SCADA
A10: 7.9 | B10: As-built documentation, training, O&M
A11: 7.10 | B11: Commissioning, glycol charge and spares
A12: 7.11 | B12: Twelve months defects liability and routine maintenance
B14: Total (excl GST)

Sheet Costing
A1: Ref | B1: Description | C1: Code | D1: Source | E1: Who does it | F1: Qty | G1: Unit | H1: Unit cost | I1: Margin | J1: Total | K1: Note
A2: 7.1 | B2: Compressor pack, including drives
B3: Compressor | C3: C-COM | D3: RFQ | F3: 2 | G3: ea | I3: 0.15 | J3: =IFERROR($F3*$H3,"") | K3: 90 kW each · IE5 VSD
A4: 7.2 | B4: Evaporative condenser
B5: Condenser | C5: C-CON | D5: RFQ | F5: 1 | G5: ea | I5: 0.15 | J5: =IFERROR($F5*$H5,"") | K5: 620 kWR each · EC Fan Supply
A6: 7.3 | B6: Chiller plate heat exchanger
B7: Chiller Phe | C7: C-HX | D7: RFQ | F7: 1 | G7: ea | I7: 0.15 | J7: =IFERROR($F7*$H7,"") | K7: 520 kWR each · no starter shown
A8: 7.4 | B8: Glycol circulation — pumps, tanks and controls
B9: Glycol Pump | C9: C-WP | D9: RFQ | F9: 2 | G9: ea | I9: 0.15 | J9: =IFERROR($F9*$H9,"") | K9: 15 kW each · VSD
B10: Defrost Pump | C10: C-WP | D10: RFQ | F10: 1 | G10: ea | I10: 0.15 | J10: =IFERROR($F10*$H10,"") | K10: 4 kW each · VSD
A11: 7.5 | B11: Unit coolers
B12: Unit Cooler | C12: C-FCU | D12: RFQ | F12: 4 | G12: ea | I12: 0.15 | J12: =IFERROR($F12*$H12,"") | K12: 55 kWR each · EC Fan Supply
A13: 7.6 | B13: Glycol pipework, valves and insulation
B14: 50TE isolating valve | C14: M-VG | D14: RFQ | F14: 10 | G14: ea | I14: 0.15 | J14: =IFERROR($F14*$H14,"") | K14: 10 × 50TE on the P&ID
B15: 50TE tube flange | C15: M-F | D15: RULE | F15: 10 | G15: ea | I15: 0.15 | J15: =IFERROR($F15*$H15,"") | K15: rule: 1 per 50TE connection
B16: 50TE gasket | C16: M-F | D16: RULE | F16: 10 | G16: ea | I16: 0.15 | J16: =IFERROR($F16*$H16,"") | K16: rule: 1 per 50TE connection
B17: 80TE isolating valve | C17: M-VG | D17: RFQ | F17: 6 | G17: ea | I17: 0.15 | J17: =IFERROR($F17*$H17,"") | K17: 6 × 80TE on the P&ID
B18: 80TE tube flange | C18: M-F | D18: RULE | F18: 6 | G18: ea | I18: 0.15 | J18: =IFERROR($F18*$H18,"") | K18: rule: 1 per 80TE connection
B19: 80TE gasket | C19: M-F | D19: RULE | F19: 6 | G19: ea | I19: 0.15 | J19: =IFERROR($F19*$H19,"") | K19: rule: 1 per 80TE connection
B20: 40PN isolating valve | C20: M-VG | D20: RFQ | F20: 2 | G20: ea | I20: 0.15 | J20: =IFERROR($F20*$H20,"") | K20: 2 × 40PN on the P&ID
B21: 40PN gasket | C21: M-F | D21: RULE | F21: 2 | G21: ea | I21: 0.15 | J21: =IFERROR($F21*$H21,"") | K21: rule: 1 per 40PN connection
B22: 40PN bolt set | C22: M-F | D22: RULE | F22: 2 | G22: ea | I22: 0.15 | J22: =IFERROR($F22*$H22,"") | K22: rule: 1 per 40PN connection
B23: 65PN isolating valve | C23: M-VG | D23: RFQ | F23: 1 | G23: ea | I23: 0.15 | J23: =IFERROR($F23*$H23,"") | K23: 1 × 65PN on the P&ID
B24: 65PN gasket | C24: M-F | D24: RULE | F24: 1 | G24: ea | I24: 0.15 | J24: =IFERROR($F24*$H24,"") | K24: rule: 1 per 65PN connection
B25: 65PN bolt set | C25: M-F | D25: RULE | F25: 1 | G25: ea | I25: 0.15 | J25: =IFERROR($F25*$H25,"") | K25: rule: 1 per 65PN connection
... B28: 65TE gasket | C28: M-F | D28: RULE | F28: 1 | G28: ea | I28: 0.15 | J28: =IFERROR($F28*$H28,"") | K28: rule: 1 per 65TE connection
B29: 42mm 304 press pipe | C29: M-PFS | D29: ENGINEER | G29: m | I29: 0.15 | J29: =IFERROR($F29*$H29,"") | K29: 8 runs on the P&ID
B30: 100NB pipe | C30: M-P | D30: ENGINEER | G30: m | I30: 0.15 | J30: =IFERROR($F30*$H30,"") | K30: 1 runs on the P&ID
B31: 80NB pipe | C31: M-P | D31: ENGINEER | G31: m | I31: 0.15 | J31: =IFERROR($F31*$H31,"") | K31: 1 runs on the P&ID
B32: 101mm tube pipe | C32: M-P | D32: ENGINEER | G32: m | I32: 0.15 | J32: =IFERROR($F32*$H32,"") | K32: 1 runs on the P&ID
B33: 63mm tube pipe | C33: M-P | D33: ENGINEER | G33: m | I33: 0.15 | J33: =IFERROR($F33*$H33,"") | K33: 1 runs on the P&ID
B34: 76mm 304 press pipe | C34: M-PFS | D34: ENGINEER | G34: m | I34: 0.15 | J34: =IFERROR($F34*$H34,"") | K34: 1 runs on the P&ID
B35: 54mm 304 press pipe | C35: M-PFS | D35: ENGINEER | G35: m | I35: 0.15 | J35: =IFERROR($F35*$H35,"") | K35: 1 runs on the P&ID
B36: Pipe insulation | C36: M-INS | D36: RATE | G36: m | I36: 0.15 | J36: =IFERROR($F36*$H36,"") | K36: rate card by diameter
B37: Freight and cartage | C37: P-FRE | D37: ENGINEER | G37: lot | I37: 0.15 | J37: =IFERROR($F37*$H37,"") | K37: carried on past jobs
A38: 7.7 | B38: Installation labour, supervision and consumables
B39: Set out and rig plant | C39: L-SERVIN | D39: ENGINEER | E39: In-house | G39: hr | H39: 105 | I39: 0.15 | J39: =IFERROR($F39*$H39,"") | K39: crew × days
B40: Pipe compressor pack | C40: L-SERVIN | D40: ENGINEER | E40: In-house | G40: hr | H40: 105 | I40: 0.15 | J40: =IFERROR($F40*$H40,"") | K40: crew × days
B41: Pipe chiller and glycol circuit | C41: L-SERVIN | D41: ENGINEER | E41: In-house | G41: hr | H41: 105 | I41: 0.15 | J41: =IFERROR($F41*$H41,"") | K41: crew × days
B42: Hang and pipe unit coolers | C42: L-SERVIN | D42: ENGINEER | E42: In-house | G42: hr | H42: 105 | I42: 0.15 | J42: =IFERROR($F42*$H42,"") | K42: crew × days
...

Sheet Electrical
A1: Load | B1: Duty | C1: Unit | D1: Starter | E1: DI | F1: DO | G1: AI | H1: RTD | I1: AO | J1: Comms | K1: IFM
A2: COMPRESSOR 1 | B2: 90 | C2: kW | D2: IE5 VSD | E2: 0 | F2: 0 | G2: 0 | H2: 0 | I2: 0 | J2: 1 | K2: 0
A3: UNIT COOLER 1 | B3: 55 | C3: kWR | D3: EC Fan Supply | E3: 0 | F3: 0 | G3: 0 | H3: 0 | I3: 0 | J3: 1 | K3: 0
A4: COMPRESSOR 2 | B4: 90 | C4: kW | D4: IE5 VSD | E4: 0 | F4: 0 | G4: 0 | H4: 0 | I4: 0 | J4: 1 | K4: 0
A5: UNIT COOLER 2 | B5: 55 | C5: kWR | D5: EC Fan Supply | E5: 0 | F5: 0 | G5: 0 | H5: 0 | I5: 0 | J5: 1 | K5: 0
A6: CONDENSER | B6: 620 | C6: kWR | D6: EC Fan Supply | E6: 0 | F6: 0 | G6: 0 | H6: 0 | I6: 0 | J6: 1 | K6: 0
A7: UNIT COOLER 3 | B7: 55 | C7: kWR | D7: EC Fan Supply | E7: 0 | F7: 0 | G7: 0 | H7: 0 | I7: 0 | J7: 1 | K7: 0
A8: CHILLER PHE | B8: 520 | C8: kWR | D8: ENGINEER | E8: ?? | F8: ?? | G8: ?? | H8: ?? | I8: ?? | J8: ?? | K8: ??
A9: GLYCOL PUMP 1 | B9: 15 | C9: kW | D9: VSD | E9: 0 | F9: 0 | G9: 0 | H9: 0 | I9: 0 | J9: 1 | K9: 0
A10: UNIT COOLER 4 | B10: 55 | C10: kWR | D10: EC Fan Supply | E10: 0 | F10: 0 | G10: 0 | H10: 0 | I10: 0 | J10: 1 | K10: 0
A11: GLYCOL PUMP 2 | B11: 15 | C11: kW | D11: VSD | E11: 0 | F11: 0 | G11: 0 | H11: 0 | I11: 0 | J11: 1 | K11: 0
A12: DEFROST PUMP | B12: 4 | C12: kW | D12: VSD | E12: 0 | F12: 0 | G12: 0 | H12: 0 | I12: 0 | J12: 1 | K12: 0
A14: TOTAL CONNECTED | B14: 1574 | C14: kW | E14: 0 | F14: 0 | G14: 0 | H14: 0 | I14: 0 | J14: 10 | K14: 0

Sheet Take-off
A1: From the P&ID | B1: Size | C1: Fitting | D1: Count | E1: Hours each | F1: Total hours | G1: Note
A2: 50TE | B2: 2" | C2: Buttweld | D2: 10 | E2: =IFERROR(INDEX('Welding hours'!$D$3:$O$14,MATCH($B2,'Welding hours'!$C$3:$C$14,0),MATCH($C2,'Welding hours'!$D$2:$O$2,0)),0) | F2: =D2*E2 | G2: counted on the drawing
A3: 50TE | B3: 2" | C3: Elbow | D3: 0 | E3: =IFERROR(INDEX('Welding hours'!$D$3:$O$14,MATCH($B3,'Welding hours'!$C$3:$C$14,0),MATCH($C3,'Welding hours'!$D$2:$O$2,0)),0) | F3: =D3*E3 | G3: counted on the drawing
A4: 80TE | B4: 3" | C4: Buttweld | D4: 6 | E4: =IFERROR(INDEX('Welding hours'!$D$3:$O$14,MATCH($B4,'Welding hours'!$C$3:$C$14,0),MATCH($C4,'Welding hours'!$D$2:$O$2,0)),0) | F4: =D4*E4 | G4: counted on the drawing
A5: 80TE | B5: 3" | C5: Elbow | D5: 0 | E5: =IFERROR(INDEX('Welding hours'!$D$3:$O$14,MATCH($B5,'Welding hours'!$C$3:$C$14,0),MATCH($C5,'Welding hours'!$D$2:$O$2,0)),0) | F5: =D5*E5 | G5: counted on the drawing
A6: 40PN | B6: 1 1/2" | C6: Buttweld | D6: 2 | E6: =IFERROR(INDEX('Welding hours'!$D$3:$O$14,MATCH($B6,'Welding hours'!$C$3:$C$14,0),MATCH($C6,'Welding hours'!$D$2:$O$2,0)),0) | F6: =D6*E6 | G6: counted on the drawing
A7: 40PN | B7: 1 1/2" | C7: Elbow | D7: 0 | E7: =IFERROR(INDEX('Welding hours'!$D$3:$O$14,MATCH($B7,'Welding hours'!$C$3:$C$14,0),MATCH($C7,'Welding hours'!$D$2:$O$2,0)),0) | F7: =D7*E7 | G7: counted on the drawing
A8: 65PN | B8: 2 1/2" | C8: Buttweld | D8: 1 | E8: =IFERROR(INDEX('Welding hours'!$D$3:$O$14,MATCH($B8,'Welding hours'!$C$3:$C$14,0),MATCH($C8,'Welding hours'!$D$2:$O$2,0)),0) | F8: =D8*E8 | G8: counted on the drawing
A9: 65PN | B9: 2 1/2" | C9: Elbow | D9: 0 | E9: =IFERROR(INDEX('Welding hours'!$D$3:$O$14,MATCH($B9,'Welding hours'!$C$3:$C$14,0),MATCH($C9,'Welding hours'!$D$2:$O$2,0)),0) | F9: =D9*E9 | G9: counted on the drawing
A10: 65TE | B10: 2 1/2" | C10: Buttweld | D10: 1 | E10: =IFERROR(INDEX('Welding hours'!$D$3:$O$14,MATCH($B10,'Welding hours'!$C$3:$C$14,0),MATCH($C10,'Welding hours'!$D$2:$O$2,0)),0) | F10: =D10*E10 | G10: counted on the drawing
A11: 65TE | B11: 2 1/2" | C11: Elbow | D11: 0 | E11: =IFERROR(INDEX('Welding hours'!$D$3:$O$14,MATCH($B11,'Welding hours'!$C$3:$C$14,0),MATCH($C11,'Welding hours'!$D$2:$O$2,0)),0) | F11: =D11*E11 | G11: counted on the drawing
A12: 42mm 304 press | B12: 1 1/2" | C12: Straight | E12: =IFERROR(INDEX('Welding hours'!$D$3:$O$14,MATCH($B12,'Welding hours'!$C$3:$C$14,0),MATCH($C12,'Welding hours'!$D$2:$O$2,0)),0) | F12: =D12*E12 | G12: metres ÷ 6 m stick → welds — enter metres
A13: 100NB | B13: 4" | C13: Straight | E13: =IFERROR(INDEX('Welding hours'!$D$3:$O$14,MATCH($B13,'Welding hours'!$C$3:$C$14,0),MATCH($C13,'Welding hours'!$D$2:$O$2,0)),0) | F13: =D13*E13 | G13: metres ÷ 6 m stick → welds — enter metres
A14: 80NB | B14: 3" | C14: Straight | E14: =IFERROR(INDEX('Welding hours'!$D$3:$O$14,MATCH($B14,'Welding hours'!$C$3:$C$14,0),MATCH($C14,'Welding hours'!$D$2:$O$2,0)),0) | F14: =D14*E14 | G14: metres ÷ 6 m stick → welds — enter metres
A15: 101mm tube | B15: 4" | C15: Straight | E15: =IFERROR(INDEX('Welding hours'!$D$3:$O$14,MATCH($B15,'Welding hours'!$C$3:$C$14,0),MATCH($C15,'Welding hours'!$D$2:$O$2,0)),0) | F15: =D15*E15 | G15: metres ÷ 6 m stick → welds — enter metres
A16: 63mm tube | B16: 2 1/2" | C16: Straight | E16: =IFERROR(INDEX('Welding hours'!$D$3:$O$14,MATCH($B16,'Welding hours'!$C$3:$C$14,0),MATCH($C16,'Welding hours'!$D$2:$O$2,0)),0) | F16: =D16*E16 | G16: metres ÷ 6 m stick → welds — enter metres
A17: 76mm 304 press | B17: 3" | C17: Straight | E17: =IFERROR(INDEX('Welding hours'!$D$3:$O$14,MATCH($B17,'Welding hours'!$C$3:$C$14,0),MATCH($C17,'Welding hours'!$D$2:$O$2,0)),0) | F17: =D17*E17 | G17: metres ÷ 6 m stick → welds — enter metres
A18: 54mm 304 press | B18: 2" | C18: Straight | E18: =IFERROR(INDEX('Welding hours'!$D$3:$O$14,MATCH($B18,'Welding hours'!$C$3:$C$14,0),MATCH($C18,'Welding hours'!$D$2:$O$2,0)),0) | F18: =D18*E18 | G18: metres ÷ 6 m stick → welds — enter metres
A20: TOTAL | F20: =SUM(F2:F18)

Sheet Welding hours
C2: Rates | D2: Weld Neck | E2: Slip On | F2: Blind | G2: Socket Weld | H2: Straight | I2: Buttweld | J2: Elbow | K2: Tee | L2: Reducer | M2: Cap | N2: Branch | O2: Stab In
C3: 1/2" | D3: 0.7 | E3: 0.7 | F3: 0.23 | G3: 0.3 | H3: 0.25 | I3: 0.5 | J3: 1 | K3: 1.5 | L3: 0.9 | M3: 0.5 | N3: 0.75 | O3: 0.45
C4: 3/4" | D4: 0.98 | E4: 0.98 | F4: 0.32 | G4: 0.42 | H4: 0.35 | I4: 0.7 | J4: 1.4 | K4: 2.1 | L4: 1.26 | M4: 0.7 | N4: 1.05 | O4: 0.63
C5: 1" | D5: 1.26 | E5: 1.26 | F5: 0.41 | G5: 0.54 | H5: 0.45 | I5: 0.9 | J5: 1.8 | K5: 2.7 | L5: 1.62 | M5: 0.9 | N5: 1.35 | O5: 0.81
C6: 1 1/4" | D6: 1.54 | E6: 1.54 | F6: 0.5 | G6: 0.66 | H6: 0.55 | I6: 1.1 | J6: 2.2 | K6: 3.3 | L6: 1.98 | M6: 1.1 | N6: 1.65 | O6: 0.99
C7: 1 1/2" | D7: 1.89 | E7: 1.89 | F7: 0.61 | G7: 0.81 | H7: 0.68 | I7: 1.35 | J7: 2.7 | K7: 4.05 | L7: 2.43 | M7: 1.35 | N7: 2.03 | O7: 1.22
C8: 2" | D8: 2.38 | E8: 2.38 | F8: 0.77 | G8: 1.02 | H8: 0.85 | I8: 1.7 | J8: 3.4 | K8: 5.1 | L8: 3.06 | M8: 1.7 | N8: 2.55 | O8: 1.53
C9: 2 1/2" | D9: 2.8 | E9: 2.8 | F9: 0.9 | G9: 1.2 | H9: 1 | I9: 2 | J9: 4 | K9: 6 | L9: 3.6 | M9: 2 | N9: 3 | O9: 1.8
C10: 3" | D10: 3.08 | E10: 3.08 | F10: 0.99 | G10: 1.32 | H10: 1.1 | I10: 2.2 | J10: 4.4 | K10: 6.6 | L10: 3.96 | M10: 2.2 | N10: 3.3 | O10: 1.98
C11: 4" | D11: 3.78 | E11: 3.78 | F11: 1.22 | G11: 1.62 | H11: 1.35 | I11: 2.7 | J11: 5.4 | K11: 8.1 | L11: 4.86 | M11: 2.7 | N11: 4.05 | O11: 2.43
C12: 5" | D12: 4.34 | E12: 4.34 | F12: 1.4 | G12: 1.86 | H12: 1.55 | I12: 3.1 | J12: 6.2 | K12: 9.3 | L12: 5.58 | M12: 3.1 | N12: 4.65 | O12: 2.79
C13: 6" | D13: 4.9 | E13: 4.9 | F13: 1.57 | G13: 2.1 | H13: 1.75 | I13: 3.5 | J13: 7 | K13: 10.5 | L13: 6.3 | M13: 3.5 | N13: 5.25 | O13: 3.15
C14: 8" | D14: 6.3 | E14: 6.3 | F14: 2.02 | G14: 2.7 | H14: 2.25 | I14: 4.5 | J14: 9 | K14: 13.5 | L14: 8.1 | M14: 4.5 | N14: 6.75 | O14: 4.05
C16: hours to weld and fit one item, by pipe size — CoolLogic's own matrix, unchanged

Sheet Rules
A1: Applies to | B1: Generates | C1: Status
A2: 1 per TE connection | B2: tube flange + gasket | C2: confirm with engineers
A3: 1 per PN connection | B3: gasket + bolt set | C3: confirm with engineers
A4: elbow | B4: 2 × a butt weld of the same size | C4: from their Labour Calculator
A5: tee | B5: 3 × a butt weld of the same size | C5: from their Labour Calculator
A6: straight pipe | B6: 1 weld per 6 m stick | C6: confirm with engineers
A7: compressor | B7: harmonic mitigation, packaged control, common return transducer | C7: observed on past jobs
A8: pump | B8: anticondensation heaters, TT/FS switch, supply transducer | C8: observed on past jobs
A9: unit cooler | B9: 2 × cold stop actuator, defrost inlet + outlet | C9: observed on past jobs
A10: condenser | B10: fan speed control, water treatment interlock, basin heater | C10: confirm with engineers
A11: pipe insulation | B11: $150 per metre by diameter | C11: rate to be set with the sub
A12: in-house vs subcontract | B12: the code changes with it: L- own labour ↔ S- subcontract, E- own electrical ↔ ES- electrical sub | C12: their own code families
... A14: Motor Starter DOL | B14: 1 DI + 1 DO + 1 AO | C14: observed on past jobs
